2017-11-08 16:52:01,283 [CASdjango.request] [Thread-3] ERROR [/Users/zy/env/webpyenv/lib/python2.7/site-packages/django/core/handlers/exception.py--line:135] Internal Server Error: /orders/product/list
Traceback (most recent call last):
  File "/Users/zy/env/webpyenv/lib/python2.7/site-packages/django/core/handlers/exception.py", line 41, in inner
    response = get_response(request)
  File "/Users/zy/env/webpyenv/lib/python2.7/site-packages/django/core/handlers/base.py", line 187, in _get_response
    response = self.process_exception_by_middleware(e, request)
  File "/Users/zy/env/webpyenv/lib/python2.7/site-packages/django/core/handlers/base.py", line 185, in _get_response
    response = wrapped_callback(request, *callback_args, **callback_kwargs)
TypeError: __init__() takes exactly 1 argument (2 given)
2017-11-08 16:56:25,563 [CASdjango.request] [Thread-1] ERROR [/Users/zy/env/webpyenv/lib/python2.7/site-packages/django/core/handlers/exception.py--line:135] Internal Server Error: /product/list
Traceback (most recent call last):
  File "/Users/zy/env/webpyenv/lib/python2.7/site-packages/django/core/handlers/exception.py", line 41, in inner
    response = get_response(request)
  File "/Users/zy/env/webpyenv/lib/python2.7/site-packages/django/core/handlers/base.py", line 187, in _get_response
    response = self.process_exception_by_middleware(e, request)
  File "/Users/zy/env/webpyenv/lib/python2.7/site-packages/django/core/handlers/base.py", line 185, in _get_response
    response = wrapped_callback(request, *callback_args, **callback_kwargs)
TypeError: __init__() takes exactly 1 argument (2 given)
2017-11-08 16:56:50,246 [CASdjango.request] [Thread-5] ERROR [/Users/zy/env/webpyenv/lib/python2.7/site-packages/django/core/handlers/exception.py--line:135] Internal Server Error: /product/list/
Traceback (most recent call last):
  File "/Users/zy/env/webpyenv/lib/python2.7/site-packages/django/core/handlers/exception.py", line 41, in inner
    response = get_response(request)
  File "/Users/zy/env/webpyenv/lib/python2.7/site-packages/django/core/handlers/base.py", line 187, in _get_response
    response = self.process_exception_by_middleware(e, request)
  File "/Users/zy/env/webpyenv/lib/python2.7/site-packages/django/core/handlers/base.py", line 185, in _get_response
    response = wrapped_callback(request, *callback_args, **callback_kwargs)
TypeError: __init__() takes exactly 1 argument (2 given)
2017-11-08 17:00:02,841 [CASdjango.request] [Thread-8] ERROR [/Users/zy/env/webpyenv/lib/python2.7/site-packages/django/core/handlers/exception.py--line:135] Internal Server Error: /product/list/
Traceback (most recent call last):
  File "/Users/zy/env/webpyenv/lib/python2.7/site-packages/django/core/handlers/exception.py", line 41, in inner
    response = get_response(request)
  File "/Users/zy/env/webpyenv/lib/python2.7/site-packages/django/core/handlers/base.py", line 187, in _get_response
    response = self.process_exception_by_middleware(e, request)
  File "/Users/zy/env/webpyenv/lib/python2.7/site-packages/django/core/handlers/base.py", line 185, in _get_response
    response = wrapped_callback(request, *callback_args, **callback_kwargs)
TypeError: __init__() takes exactly 1 argument (2 given)
2017-11-08 17:01:03,343 [CASdjango.request] [Thread-14] ERROR [/Users/zy/env/webpyenv/lib/python2.7/site-packages/django/core/handlers/exception.py--line:135] Internal Server Error: /product/list/
Traceback (most recent call last):
  File "/Users/zy/env/webpyenv/lib/python2.7/site-packages/django/core/handlers/exception.py", line 41, in inner
    response = get_response(request)
  File "/Users/zy/env/webpyenv/lib/python2.7/site-packages/django/core/handlers/base.py", line 187, in _get_response
    response = self.process_exception_by_middleware(e, request)
  File "/Users/zy/env/webpyenv/lib/python2.7/site-packages/django/core/handlers/base.py", line 185, in _get_response
    response = wrapped_callback(request, *callback_args, **callback_kwargs)
TypeError: __init__() takes exactly 1 argument (2 given)
2017-11-08 17:08:13,586 [CASdjango.request] [Thread-1] ERROR [/Users/zy/env/webpyenv/lib/python2.7/site-packages/django/core/handlers/exception.py--line:135] Internal Server Error: /
Traceback (most recent call last):
  File "/Users/zy/env/webpyenv/lib/python2.7/site-packages/django/core/handlers/exception.py", line 41, in inner
    response = get_response(request)
  File "/Users/zy/env/webpyenv/lib/python2.7/site-packages/django/core/handlers/base.py", line 187, in _get_response
    response = self.process_exception_by_middleware(e, request)
  File "/Users/zy/env/webpyenv/lib/python2.7/site-packages/django/core/handlers/base.py", line 185, in _get_response
    response = wrapped_callback(request, *callback_args, **callback_kwargs)
  File "/Users/zy/Project/wjnhadmin/wjnhadmin/views.py", line 12, in index
    return render(request, 'index.html', {})
  File "/Users/zy/env/webpyenv/lib/python2.7/site-packages/django/shortcuts.py", line 30, in render
    content = loader.render_to_string(template_name, context, request, using=using)
  File "/Users/zy/env/webpyenv/lib/python2.7/site-packages/django/template/loader.py", line 67, in render_to_string
    template = get_template(template_name, using=using)
  File "/Users/zy/env/webpyenv/lib/python2.7/site-packages/django/template/loader.py", line 18, in get_template
    engines = _engine_list(using)
  File "/Users/zy/env/webpyenv/lib/python2.7/site-packages/django/template/loader.py", line 72, in _engine_list
    return engines.all() if using is None else [engines[using]]
  File "/Users/zy/env/webpyenv/lib/python2.7/site-packages/django/template/utils.py", line 89, in all
    return [self[alias] for alias in self]
  File "/Users/zy/env/webpyenv/lib/python2.7/site-packages/django/template/utils.py", line 80, in __getitem__
    engine = engine_cls(params)
  File "/Users/zy/env/webpyenv/lib/python2.7/site-packages/django/template/backends/django.py", line 31, in __init__
    super(DjangoTemplates, self).__init__(params)
  File "/Users/zy/env/webpyenv/lib/python2.7/site-packages/django/template/backends/base.py", line 29, in __init__
    "Unknown parameters: {}".format(", ".join(params)))
ImproperlyConfigured: Unknown parameters: TEMPLATE_DEBUG
2017-11-08 17:10:04,940 [CASdjango.request] [Thread-12] ERROR [/Users/zy/env/webpyenv/lib/python2.7/site-packages/django/core/handlers/exception.py--line:135] Internal Server Error: /product/list/
Traceback (most recent call last):
  File "/Users/zy/env/webpyenv/lib/python2.7/site-packages/django/core/handlers/exception.py", line 41, in inner
    response = get_response(request)
  File "/Users/zy/env/webpyenv/lib/python2.7/site-packages/django/core/handlers/base.py", line 187, in _get_response
    response = self.process_exception_by_middleware(e, request)
  File "/Users/zy/env/webpyenv/lib/python2.7/site-packages/django/core/handlers/base.py", line 185, in _get_response
    response = wrapped_callback(request, *callback_args, **callback_kwargs)
TypeError: __init__() takes exactly 1 argument (2 given)
2017-11-08 17:13:27,372 [CASdjango.request] [Thread-4] ERROR [/Users/zy/env/webpyenv/lib/python2.7/site-packages/django/core/handlers/exception.py--line:135] Internal Server Error: /product/list/
Traceback (most recent call last):
  File "/Users/zy/env/webpyenv/lib/python2.7/site-packages/django/core/handlers/exception.py", line 41, in inner
    response = get_response(request)
  File "/Users/zy/env/webpyenv/lib/python2.7/site-packages/django/core/handlers/base.py", line 187, in _get_response
    response = self.process_exception_by_middleware(e, request)
  File "/Users/zy/env/webpyenv/lib/python2.7/site-packages/django/core/handlers/base.py", line 185, in _get_response
    response = wrapped_callback(request, *callback_args, **callback_kwargs)
TypeError: __init__() takes exactly 1 argument (2 given)
2017-11-08 17:15:36,985 [CASdjango.request] [Thread-6] ERROR [/Users/zy/env/webpyenv/lib/python2.7/site-packages/django/core/handlers/exception.py--line:135] Internal Server Error: /product/list/
Traceback (most recent call last):
  File "/Users/zy/env/webpyenv/lib/python2.7/site-packages/django/core/handlers/exception.py", line 41, in inner
    response = get_response(request)
  File "/Users/zy/env/webpyenv/lib/python2.7/site-packages/django/core/handlers/base.py", line 187, in _get_response
    response = self.process_exception_by_middleware(e, request)
  File "/Users/zy/env/webpyenv/lib/python2.7/site-packages/django/core/handlers/base.py", line 185, in _get_response
    response = wrapped_callback(request, *callback_args, **callback_kwargs)
TypeError: __init__() takes exactly 1 argument (2 given)
2017-11-08 17:16:08,932 [CASdjango.request] [Thread-1] ERROR [/Users/zy/env/webpyenv/lib/python2.7/site-packages/django/core/handlers/exception.py--line:135] Internal Server Error: /product/list/
Traceback (most recent call last):
  File "/Users/zy/env/webpyenv/lib/python2.7/site-packages/django/core/handlers/exception.py", line 41, in inner
    response = get_response(request)
  File "/Users/zy/env/webpyenv/lib/python2.7/site-packages/django/core/handlers/base.py", line 187, in _get_response
    response = self.process_exception_by_middleware(e, request)
  File "/Users/zy/env/webpyenv/lib/python2.7/site-packages/django/core/handlers/base.py", line 185, in _get_response
    response = wrapped_callback(request, *callback_args, **callback_kwargs)
TypeError: __init__() takes exactly 1 argument (2 given)
2017-11-08 17:17:02,105 [CASdjango.request] [Thread-3] ERROR [/Users/zy/env/webpyenv/lib/python2.7/site-packages/django/core/handlers/exception.py--line:135] Internal Server Error: /product/list/
Traceback (most recent call last):
  File "/Users/zy/env/webpyenv/lib/python2.7/site-packages/django/core/handlers/exception.py", line 41, in inner
    response = get_response(request)
  File "/Users/zy/env/webpyenv/lib/python2.7/site-packages/django/core/handlers/base.py", line 187, in _get_response
    response = self.process_exception_by_middleware(e, request)
  File "/Users/zy/env/webpyenv/lib/python2.7/site-packages/django/core/handlers/base.py", line 185, in _get_response
    response = wrapped_callback(request, *callback_args, **callback_kwargs)
TypeError: __init__() takes exactly 1 argument (2 given)
2017-11-08 17:17:07,185 [CASdjango.request] [Thread-1] ERROR [/Users/zy/env/webpyenv/lib/python2.7/site-packages/django/core/handlers/exception.py--line:135] Internal Server Error: /product/list/
Traceback (most recent call last):
  File "/Users/zy/env/webpyenv/lib/python2.7/site-packages/django/core/handlers/exception.py", line 41, in inner
    response = get_response(request)
  File "/Users/zy/env/webpyenv/lib/python2.7/site-packages/django/core/handlers/base.py", line 187, in _get_response
    response = self.process_exception_by_middleware(e, request)
  File "/Users/zy/env/webpyenv/lib/python2.7/site-packages/django/core/handlers/base.py", line 185, in _get_response
    response = wrapped_callback(request, *callback_args, **callback_kwargs)
TypeError: __init__() takes exactly 1 argument (2 given)
2017-11-08 17:18:19,838 [CASdjango.request] [Thread-1] ERROR [/Users/zy/env/webpyenv/lib/python2.7/site-packages/django/core/handlers/exception.py--line:135] Internal Server Error: /product/list/
Traceback (most recent call last):
  File "/Users/zy/env/webpyenv/lib/python2.7/site-packages/django/core/handlers/exception.py", line 41, in inner
    response = get_response(request)
  File "/Users/zy/env/webpyenv/lib/python2.7/site-packages/django/core/handlers/base.py", line 187, in _get_response
    response = self.process_exception_by_middleware(e, request)
  File "/Users/zy/env/webpyenv/lib/python2.7/site-packages/django/core/handlers/base.py", line 185, in _get_response
    response = wrapped_callback(request, *callback_args, **callback_kwargs)
  File "/Users/zy/env/webpyenv/lib/python2.7/site-packages/django/views/generic/base.py", line 68, in view
    return self.dispatch(request, *args, **kwargs)
  File "/Users/zy/env/webpyenv/lib/python2.7/site-packages/django/views/generic/base.py", line 88, in dispatch
    return handler(request, *args, **kwargs)
  File "/Users/zy/env/webpyenv/lib/python2.7/site-packages/django/views/generic/list.py", line 175, in get
    context = self.get_context_data()
  File "/Users/zy/Project/wjnhadmin/orders/views.py", line 25, in get_context_data
    context = super(ProductList, self).get_context_data(**kwargs)
  File "/Users/zy/env/webpyenv/lib/python2.7/site-packages/django/views/generic/list.py", line 135, in get_context_data
    paginator, page, queryset, is_paginated = self.paginate_queryset(queryset, page_size)
  File "/Users/zy/env/webpyenv/lib/python2.7/site-packages/django/views/generic/list.py", line 79, in paginate_queryset
    page = paginator.page(page_number)
  File "/Users/zy/env/webpyenv/lib/python2.7/site-packages/django/core/paginator.py", line 57, in page
    number = self.validate_number(number)
  File "/Users/zy/env/webpyenv/lib/python2.7/site-packages/django/core/paginator.py", line 46, in validate_number
    if number > self.num_pages:
  File "/Users/zy/env/webpyenv/lib/python2.7/site-packages/django/utils/functional.py", line 35, in __get__
    res = instance.__dict__[self.name] = self.func(instance)
  File "/Users/zy/env/webpyenv/lib/python2.7/site-packages/django/core/paginator.py", line 91, in num_pages
    if self.count == 0 and not self.allow_empty_first_page:
  File "/Users/zy/env/webpyenv/lib/python2.7/site-packages/django/utils/functional.py", line 35, in __get__
    res = instance.__dict__[self.name] = self.func(instance)
  File "/Users/zy/env/webpyenv/lib/python2.7/site-packages/django/core/paginator.py", line 79, in count
    return self.object_list.count()
  File "/Users/zy/env/webpyenv/lib/python2.7/site-packages/django/db/models/query.py", line 364, in count
    return self.query.get_count(using=self.db)
  File "/Users/zy/env/webpyenv/lib/python2.7/site-packages/django/db/models/sql/query.py", line 499, in get_count
    number = obj.get_aggregation(using, ['__count'])['__count']
  File "/Users/zy/env/webpyenv/lib/python2.7/site-packages/django/db/models/sql/query.py", line 480, in get_aggregation
    result = compiler.execute_sql(SINGLE)
  File "/Users/zy/env/webpyenv/lib/python2.7/site-packages/django/db/models/sql/compiler.py", line 894, in execute_sql
    raise original_exception
ProgrammingError: (1146, "Table 'admin.product' doesn't exist")
2017-11-08 17:18:22,422 [CASdjango.request] [Thread-3] ERROR [/Users/zy/env/webpyenv/lib/python2.7/site-packages/django/core/handlers/exception.py--line:135] Internal Server Error: /product/list/
Traceback (most recent call last):
  File "/Users/zy/env/webpyenv/lib/python2.7/site-packages/django/core/handlers/exception.py", line 41, in inner
    response = get_response(request)
  File "/Users/zy/env/webpyenv/lib/python2.7/site-packages/django/core/handlers/base.py", line 187, in _get_response
    response = self.process_exception_by_middleware(e, request)
  File "/Users/zy/env/webpyenv/lib/python2.7/site-packages/django/core/handlers/base.py", line 185, in _get_response
    response = wrapped_callback(request, *callback_args, **callback_kwargs)
  File "/Users/zy/env/webpyenv/lib/python2.7/site-packages/django/views/generic/base.py", line 68, in view
    return self.dispatch(request, *args, **kwargs)
  File "/Users/zy/env/webpyenv/lib/python2.7/site-packages/django/views/generic/base.py", line 88, in dispatch
    return handler(request, *args, **kwargs)
  File "/Users/zy/env/webpyenv/lib/python2.7/site-packages/django/views/generic/list.py", line 175, in get
    context = self.get_context_data()
  File "/Users/zy/Project/wjnhadmin/orders/views.py", line 25, in get_context_data
    context = super(ProductList, self).get_context_data(**kwargs)
  File "/Users/zy/env/webpyenv/lib/python2.7/site-packages/django/views/generic/list.py", line 135, in get_context_data
    paginator, page, queryset, is_paginated = self.paginate_queryset(queryset, page_size)
  File "/Users/zy/env/webpyenv/lib/python2.7/site-packages/django/views/generic/list.py", line 79, in paginate_queryset
    page = paginator.page(page_number)
  File "/Users/zy/env/webpyenv/lib/python2.7/site-packages/django/core/paginator.py", line 57, in page
    number = self.validate_number(number)
  File "/Users/zy/env/webpyenv/lib/python2.7/site-packages/django/core/paginator.py", line 46, in validate_number
    if number > self.num_pages:
  File "/Users/zy/env/webpyenv/lib/python2.7/site-packages/django/utils/functional.py", line 35, in __get__
    res = instance.__dict__[self.name] = self.func(instance)
  File "/Users/zy/env/webpyenv/lib/python2.7/site-packages/django/core/paginator.py", line 91, in num_pages
    if self.count == 0 and not self.allow_empty_first_page:
  File "/Users/zy/env/webpyenv/lib/python2.7/site-packages/django/utils/functional.py", line 35, in __get__
    res = instance.__dict__[self.name] = self.func(instance)
  File "/Users/zy/env/webpyenv/lib/python2.7/site-packages/django/core/paginator.py", line 79, in count
    return self.object_list.count()
  File "/Users/zy/env/webpyenv/lib/python2.7/site-packages/django/db/models/query.py", line 364, in count
    return self.query.get_count(using=self.db)
  File "/Users/zy/env/webpyenv/lib/python2.7/site-packages/django/db/models/sql/query.py", line 499, in get_count
    number = obj.get_aggregation(using, ['__count'])['__count']
  File "/Users/zy/env/webpyenv/lib/python2.7/site-packages/django/db/models/sql/query.py", line 480, in get_aggregation
    result = compiler.execute_sql(SINGLE)
  File "/Users/zy/env/webpyenv/lib/python2.7/site-packages/django/db/models/sql/compiler.py", line 894, in execute_sql
    raise original_exception
ProgrammingError: (1146, "Table 'admin.product' doesn't exist")
2017-11-08 17:18:24,013 [CASdjango.request] [Thread-4] ERROR [/Users/zy/env/webpyenv/lib/python2.7/site-packages/django/core/handlers/exception.py--line:135] Internal Server Error: /product/list/
Traceback (most recent call last):
  File "/Users/zy/env/webpyenv/lib/python2.7/site-packages/django/core/handlers/exception.py", line 41, in inner
    response = get_response(request)
  File "/Users/zy/env/webpyenv/lib/python2.7/site-packages/django/core/handlers/base.py", line 187, in _get_response
    response = self.process_exception_by_middleware(e, request)
  File "/Users/zy/env/webpyenv/lib/python2.7/site-packages/django/core/handlers/base.py", line 185, in _get_response
    response = wrapped_callback(request, *callback_args, **callback_kwargs)
  File "/Users/zy/env/webpyenv/lib/python2.7/site-packages/django/views/generic/base.py", line 68, in view
    return self.dispatch(request, *args, **kwargs)
  File "/Users/zy/env/webpyenv/lib/python2.7/site-packages/django/views/generic/base.py", line 88, in dispatch
    return handler(request, *args, **kwargs)
  File "/Users/zy/env/webpyenv/lib/python2.7/site-packages/django/views/generic/list.py", line 175, in get
    context = self.get_context_data()
  File "/Users/zy/Project/wjnhadmin/orders/views.py", line 25, in get_context_data
    context = super(ProductList, self).get_context_data(**kwargs)
  File "/Users/zy/env/webpyenv/lib/python2.7/site-packages/django/views/generic/list.py", line 135, in get_context_data
    paginator, page, queryset, is_paginated = self.paginate_queryset(queryset, page_size)
  File "/Users/zy/env/webpyenv/lib/python2.7/site-packages/django/views/generic/list.py", line 79, in paginate_queryset
    page = paginator.page(page_number)
  File "/Users/zy/env/webpyenv/lib/python2.7/site-packages/django/core/paginator.py", line 57, in page
    number = self.validate_number(number)
  File "/Users/zy/env/webpyenv/lib/python2.7/site-packages/django/core/paginator.py", line 46, in validate_number
    if number > self.num_pages:
  File "/Users/zy/env/webpyenv/lib/python2.7/site-packages/django/utils/functional.py", line 35, in __get__
    res = instance.__dict__[self.name] = self.func(instance)
  File "/Users/zy/env/webpyenv/lib/python2.7/site-packages/django/core/paginator.py", line 91, in num_pages
    if self.count == 0 and not self.allow_empty_first_page:
  File "/Users/zy/env/webpyenv/lib/python2.7/site-packages/django/utils/functional.py", line 35, in __get__
    res = instance.__dict__[self.name] = self.func(instance)
  File "/Users/zy/env/webpyenv/lib/python2.7/site-packages/django/core/paginator.py", line 79, in count
    return self.object_list.count()
  File "/Users/zy/env/webpyenv/lib/python2.7/site-packages/django/db/models/query.py", line 364, in count
    return self.query.get_count(using=self.db)
  File "/Users/zy/env/webpyenv/lib/python2.7/site-packages/django/db/models/sql/query.py", line 499, in get_count
    number = obj.get_aggregation(using, ['__count'])['__count']
  File "/Users/zy/env/webpyenv/lib/python2.7/site-packages/django/db/models/sql/query.py", line 480, in get_aggregation
    result = compiler.execute_sql(SINGLE)
  File "/Users/zy/env/webpyenv/lib/python2.7/site-packages/django/db/models/sql/compiler.py", line 894, in execute_sql
    raise original_exception
ProgrammingError: (1146, "Table 'admin.product' doesn't exist")
2017-11-08 17:18:25,503 [CASdjango.request] [Thread-5] ERROR [/Users/zy/env/webpyenv/lib/python2.7/site-packages/django/core/handlers/exception.py--line:135] Internal Server Error: /product/list/
Traceback (most recent call last):
  File "/Users/zy/env/webpyenv/lib/python2.7/site-packages/django/core/handlers/exception.py", line 41, in inner
    response = get_response(request)
  File "/Users/zy/env/webpyenv/lib/python2.7/site-packages/django/core/handlers/base.py", line 187, in _get_response
    response = self.process_exception_by_middleware(e, request)
  File "/Users/zy/env/webpyenv/lib/python2.7/site-packages/django/core/handlers/base.py", line 185, in _get_response
    response = wrapped_callback(request, *callback_args, **callback_kwargs)
  File "/Users/zy/env/webpyenv/lib/python2.7/site-packages/django/views/generic/base.py", line 68, in view
    return self.dispatch(request, *args, **kwargs)
  File "/Users/zy/env/webpyenv/lib/python2.7/site-packages/django/views/generic/base.py", line 88, in dispatch
    return handler(request, *args, **kwargs)
  File "/Users/zy/env/webpyenv/lib/python2.7/site-packages/django/views/generic/list.py", line 175, in get
    context = self.get_context_data()
  File "/Users/zy/Project/wjnhadmin/orders/views.py", line 25, in get_context_data
    context = super(ProductList, self).get_context_data(**kwargs)
  File "/Users/zy/env/webpyenv/lib/python2.7/site-packages/django/views/generic/list.py", line 135, in get_context_data
    paginator, page, queryset, is_paginated = self.paginate_queryset(queryset, page_size)
  File "/Users/zy/env/webpyenv/lib/python2.7/site-packages/django/views/generic/list.py", line 79, in paginate_queryset
    page = paginator.page(page_number)
  File "/Users/zy/env/webpyenv/lib/python2.7/site-packages/django/core/paginator.py", line 57, in page
    number = self.validate_number(number)
  File "/Users/zy/env/webpyenv/lib/python2.7/site-packages/django/core/paginator.py", line 46, in validate_number
    if number > self.num_pages:
  File "/Users/zy/env/webpyenv/lib/python2.7/site-packages/django/utils/functional.py", line 35, in __get__
    res = instance.__dict__[self.name] = self.func(instance)
  File "/Users/zy/env/webpyenv/lib/python2.7/site-packages/django/core/paginator.py", line 91, in num_pages
    if self.count == 0 and not self.allow_empty_first_page:
  File "/Users/zy/env/webpyenv/lib/python2.7/site-packages/django/utils/functional.py", line 35, in __get__
    res = instance.__dict__[self.name] = self.func(instance)
  File "/Users/zy/env/webpyenv/lib/python2.7/site-packages/django/core/paginator.py", line 79, in count
    return self.object_list.count()
  File "/Users/zy/env/webpyenv/lib/python2.7/site-packages/django/db/models/query.py", line 364, in count
    return self.query.get_count(using=self.db)
  File "/Users/zy/env/webpyenv/lib/python2.7/site-packages/django/db/models/sql/query.py", line 499, in get_count
    number = obj.get_aggregation(using, ['__count'])['__count']
  File "/Users/zy/env/webpyenv/lib/python2.7/site-packages/django/db/models/sql/query.py", line 480, in get_aggregation
    result = compiler.execute_sql(SINGLE)
  File "/Users/zy/env/webpyenv/lib/python2.7/site-packages/django/db/models/sql/compiler.py", line 894, in execute_sql
    raise original_exception
ProgrammingError: (1146, "Table 'admin.product' doesn't exist")
2017-11-08 17:18:26,298 [CASdjango.request] [Thread-6] ERROR [/Users/zy/env/webpyenv/lib/python2.7/site-packages/django/core/handlers/exception.py--line:135] Internal Server Error: /product/list/
Traceback (most recent call last):
  File "/Users/zy/env/webpyenv/lib/python2.7/site-packages/django/core/handlers/exception.py", line 41, in inner
    response = get_response(request)
  File "/Users/zy/env/webpyenv/lib/python2.7/site-packages/django/core/handlers/base.py", line 187, in _get_response
    response = self.process_exception_by_middleware(e, request)
  File "/Users/zy/env/webpyenv/lib/python2.7/site-packages/django/core/handlers/base.py", line 185, in _get_response
    response = wrapped_callback(request, *callback_args, **callback_kwargs)
  File "/Users/zy/env/webpyenv/lib/python2.7/site-packages/django/views/generic/base.py", line 68, in view
    return self.dispatch(request, *args, **kwargs)
  File "/Users/zy/env/webpyenv/lib/python2.7/site-packages/django/views/generic/base.py", line 88, in dispatch
    return handler(request, *args, **kwargs)
  File "/Users/zy/env/webpyenv/lib/python2.7/site-packages/django/views/generic/list.py", line 175, in get
    context = self.get_context_data()
  File "/Users/zy/Project/wjnhadmin/orders/views.py", line 25, in get_context_data
    context = super(ProductList, self).get_context_data(**kwargs)
  File "/Users/zy/env/webpyenv/lib/python2.7/site-packages/django/views/generic/list.py", line 135, in get_context_data
    paginator, page, queryset, is_paginated = self.paginate_queryset(queryset, page_size)
  File "/Users/zy/env/webpyenv/lib/python2.7/site-packages/django/views/generic/list.py", line 79, in paginate_queryset
    page = paginator.page(page_number)
  File "/Users/zy/env/webpyenv/lib/python2.7/site-packages/django/core/paginator.py", line 57, in page
    number = self.validate_number(number)
  File "/Users/zy/env/webpyenv/lib/python2.7/site-packages/django/core/paginator.py", line 46, in validate_number
    if number > self.num_pages:
  File "/Users/zy/env/webpyenv/lib/python2.7/site-packages/django/utils/functional.py", line 35, in __get__
    res = instance.__dict__[self.name] = self.func(instance)
  File "/Users/zy/env/webpyenv/lib/python2.7/site-packages/django/core/paginator.py", line 91, in num_pages
    if self.count == 0 and not self.allow_empty_first_page:
  File "/Users/zy/env/webpyenv/lib/python2.7/site-packages/django/utils/functional.py", line 35, in __get__
    res = instance.__dict__[self.name] = self.func(instance)
  File "/Users/zy/env/webpyenv/lib/python2.7/site-packages/django/core/paginator.py", line 79, in count
    return self.object_list.count()
  File "/Users/zy/env/webpyenv/lib/python2.7/site-packages/django/db/models/query.py", line 364, in count
    return self.query.get_count(using=self.db)
  File "/Users/zy/env/webpyenv/lib/python2.7/site-packages/django/db/models/sql/query.py", line 499, in get_count
    number = obj.get_aggregation(using, ['__count'])['__count']
  File "/Users/zy/env/webpyenv/lib/python2.7/site-packages/django/db/models/sql/query.py", line 480, in get_aggregation
    result = compiler.execute_sql(SINGLE)
  File "/Users/zy/env/webpyenv/lib/python2.7/site-packages/django/db/models/sql/compiler.py", line 894, in execute_sql
    raise original_exception
ProgrammingError: (1146, "Table 'admin.product' doesn't exist")
2017-11-08 17:18:27,160 [CASdjango.request] [Thread-7] ERROR [/Users/zy/env/webpyenv/lib/python2.7/site-packages/django/core/handlers/exception.py--line:135] Internal Server Error: /product/list/
Traceback (most recent call last):
  File "/Users/zy/env/webpyenv/lib/python2.7/site-packages/django/core/handlers/exception.py", line 41, in inner
    response = get_response(request)
  File "/Users/zy/env/webpyenv/lib/python2.7/site-packages/django/core/handlers/base.py", line 187, in _get_response
    response = self.process_exception_by_middleware(e, request)
  File "/Users/zy/env/webpyenv/lib/python2.7/site-packages/django/core/handlers/base.py", line 185, in _get_response
    response = wrapped_callback(request, *callback_args, **callback_kwargs)
  File "/Users/zy/env/webpyenv/lib/python2.7/site-packages/django/views/generic/base.py", line 68, in view
    return self.dispatch(request, *args, **kwargs)
  File "/Users/zy/env/webpyenv/lib/python2.7/site-packages/django/views/generic/base.py", line 88, in dispatch
    return handler(request, *args, **kwargs)
  File "/Users/zy/env/webpyenv/lib/python2.7/site-packages/django/views/generic/list.py", line 175, in get
    context = self.get_context_data()
  File "/Users/zy/Project/wjnhadmin/orders/views.py", line 25, in get_context_data
    context = super(ProductList, self).get_context_data(**kwargs)
  File "/Users/zy/env/webpyenv/lib/python2.7/site-packages/django/views/generic/list.py", line 135, in get_context_data
    paginator, page, queryset, is_paginated = self.paginate_queryset(queryset, page_size)
  File "/Users/zy/env/webpyenv/lib/python2.7/site-packages/django/views/generic/list.py", line 79, in paginate_queryset
    page = paginator.page(page_number)
  File "/Users/zy/env/webpyenv/lib/python2.7/site-packages/django/core/paginator.py", line 57, in page
    number = self.validate_number(number)
  File "/Users/zy/env/webpyenv/lib/python2.7/site-packages/django/core/paginator.py", line 46, in validate_number
    if number > self.num_pages:
  File "/Users/zy/env/webpyenv/lib/python2.7/site-packages/django/utils/functional.py", line 35, in __get__
    res = instance.__dict__[self.name] = self.func(instance)
  File "/Users/zy/env/webpyenv/lib/python2.7/site-packages/django/core/paginator.py", line 91, in num_pages
    if self.count == 0 and not self.allow_empty_first_page:
  File "/Users/zy/env/webpyenv/lib/python2.7/site-packages/django/utils/functional.py", line 35, in __get__
    res = instance.__dict__[self.name] = self.func(instance)
  File "/Users/zy/env/webpyenv/lib/python2.7/site-packages/django/core/paginator.py", line 79, in count
    return self.object_list.count()
  File "/Users/zy/env/webpyenv/lib/python2.7/site-packages/django/db/models/query.py", line 364, in count
    return self.query.get_count(using=self.db)
  File "/Users/zy/env/webpyenv/lib/python2.7/site-packages/django/db/models/sql/query.py", line 499, in get_count
    number = obj.get_aggregation(using, ['__count'])['__count']
  File "/Users/zy/env/webpyenv/lib/python2.7/site-packages/django/db/models/sql/query.py", line 480, in get_aggregation
    result = compiler.execute_sql(SINGLE)
  File "/Users/zy/env/webpyenv/lib/python2.7/site-packages/django/db/models/sql/compiler.py", line 894, in execute_sql
    raise original_exception
ProgrammingError: (1146, "Table 'admin.product' doesn't exist")
2017-11-08 17:18:27,927 [CASdjango.request] [Thread-8] ERROR [/Users/zy/env/webpyenv/lib/python2.7/site-packages/django/core/handlers/exception.py--line:135] Internal Server Error: /product/list/
Traceback (most recent call last):
  File "/Users/zy/env/webpyenv/lib/python2.7/site-packages/django/core/handlers/exception.py", line 41, in inner
    response = get_response(request)
  File "/Users/zy/env/webpyenv/lib/python2.7/site-packages/django/core/handlers/base.py", line 187, in _get_response
    response = self.process_exception_by_middleware(e, request)
  File "/Users/zy/env/webpyenv/lib/python2.7/site-packages/django/core/handlers/base.py", line 185, in _get_response
    response = wrapped_callback(request, *callback_args, **callback_kwargs)
  File "/Users/zy/env/webpyenv/lib/python2.7/site-packages/django/views/generic/base.py", line 68, in view
    return self.dispatch(request, *args, **kwargs)
  File "/Users/zy/env/webpyenv/lib/python2.7/site-packages/django/views/generic/base.py", line 88, in dispatch
    return handler(request, *args, **kwargs)
  File "/Users/zy/env/webpyenv/lib/python2.7/site-packages/django/views/generic/list.py", line 175, in get
    context = self.get_context_data()
  File "/Users/zy/Project/wjnhadmin/orders/views.py", line 25, in get_context_data
    context = super(ProductList, self).get_context_data(**kwargs)
  File "/Users/zy/env/webpyenv/lib/python2.7/site-packages/django/views/generic/list.py", line 135, in get_context_data
    paginator, page, queryset, is_paginated = self.paginate_queryset(queryset, page_size)
  File "/Users/zy/env/webpyenv/lib/python2.7/site-packages/django/views/generic/list.py", line 79, in paginate_queryset
    page = paginator.page(page_number)
  File "/Users/zy/env/webpyenv/lib/python2.7/site-packages/django/core/paginator.py", line 57, in page
    number = self.validate_number(number)
  File "/Users/zy/env/webpyenv/lib/python2.7/site-packages/django/core/paginator.py", line 46, in validate_number
    if number > self.num_pages:
  File "/Users/zy/env/webpyenv/lib/python2.7/site-packages/django/utils/functional.py", line 35, in __get__
    res = instance.__dict__[self.name] = self.func(instance)
  File "/Users/zy/env/webpyenv/lib/python2.7/site-packages/django/core/paginator.py", line 91, in num_pages
    if self.count == 0 and not self.allow_empty_first_page:
  File "/Users/zy/env/webpyenv/lib/python2.7/site-packages/django/utils/functional.py", line 35, in __get__
    res = instance.__dict__[self.name] = self.func(instance)
  File "/Users/zy/env/webpyenv/lib/python2.7/site-packages/django/core/paginator.py", line 79, in count
    return self.object_list.count()
  File "/Users/zy/env/webpyenv/lib/python2.7/site-packages/django/db/models/query.py", line 364, in count
    return self.query.get_count(using=self.db)
  File "/Users/zy/env/webpyenv/lib/python2.7/site-packages/django/db/models/sql/query.py", line 499, in get_count
    number = obj.get_aggregation(using, ['__count'])['__count']
  File "/Users/zy/env/webpyenv/lib/python2.7/site-packages/django/db/models/sql/query.py", line 480, in get_aggregation
    result = compiler.execute_sql(SINGLE)
  File "/Users/zy/env/webpyenv/lib/python2.7/site-packages/django/db/models/sql/compiler.py", line 894, in execute_sql
    raise original_exception
ProgrammingError: (1146, "Table 'admin.product' doesn't exist")
2017-11-08 17:23:33,610 [CASdjango.request] [Thread-6] ERROR [/Users/zy/env/webpyenv/lib/python2.7/site-packages/django/core/handlers/exception.py--line:135] Internal Server Error: /product/list/
Traceback (most recent call last):
  File "/Users/zy/env/webpyenv/lib/python2.7/site-packages/django/core/handlers/exception.py", line 41, in inner
    response = get_response(request)
  File "/Users/zy/env/webpyenv/lib/python2.7/site-packages/django/core/handlers/base.py", line 217, in _get_response
    response = self.process_exception_by_middleware(e, request)
  File "/Users/zy/env/webpyenv/lib/python2.7/site-packages/django/core/handlers/base.py", line 215, in _get_response
    response = response.render()
  File "/Users/zy/env/webpyenv/lib/python2.7/site-packages/django/template/response.py", line 107, in render
    self.content = self.rendered_content
  File "/Users/zy/env/webpyenv/lib/python2.7/site-packages/django/template/response.py", line 82, in rendered_content
    template = self.resolve_template(self.template_name)
  File "/Users/zy/env/webpyenv/lib/python2.7/site-packages/django/template/response.py", line 64, in resolve_template
    return select_template(template, using=self.using)
  File "/Users/zy/env/webpyenv/lib/python2.7/site-packages/django/template/loader.py", line 48, in select_template
    return engine.get_template(template_name)
  File "/Users/zy/env/webpyenv/lib/python2.7/site-packages/django/template/backends/django.py", line 39, in get_template
    return Template(self.engine.get_template(template_name), self)
  File "/Users/zy/env/webpyenv/lib/python2.7/site-packages/django/template/engine.py", line 162, in get_template
    template, origin = self.find_template(template_name)
  File "/Users/zy/env/webpyenv/lib/python2.7/site-packages/django/template/engine.py", line 136, in find_template
    name, template_dirs=dirs, skip=skip,
  File "/Users/zy/env/webpyenv/lib/python2.7/site-packages/django/template/loaders/base.py", line 44, in get_template
    contents, origin, origin.template_name, self.engine,
  File "/Users/zy/env/webpyenv/lib/python2.7/site-packages/django/template/base.py", line 191, in __init__
    self.nodelist = self.compile_nodelist()
  File "/Users/zy/env/webpyenv/lib/python2.7/site-packages/django/template/base.py", line 230, in compile_nodelist
    return parser.parse()
  File "/Users/zy/env/webpyenv/lib/python2.7/site-packages/django/template/base.py", line 515, in parse
    raise self.error(token, e)
TemplateSyntaxError: Invalid block tag on line 58: 'bootstrap_pagination', expected 'endblock'. Did you forget to register or load this tag?
2017-11-08 17:23:34,714 [CASdjango.request] [Thread-7] ERROR [/Users/zy/env/webpyenv/lib/python2.7/site-packages/django/core/handlers/exception.py--line:135] Internal Server Error: /product/list/
Traceback (most recent call last):
  File "/Users/zy/env/webpyenv/lib/python2.7/site-packages/django/core/handlers/exception.py", line 41, in inner
    response = get_response(request)
  File "/Users/zy/env/webpyenv/lib/python2.7/site-packages/django/core/handlers/base.py", line 217, in _get_response
    response = self.process_exception_by_middleware(e, request)
  File "/Users/zy/env/webpyenv/lib/python2.7/site-packages/django/core/handlers/base.py", line 215, in _get_response
    response = response.render()
  File "/Users/zy/env/webpyenv/lib/python2.7/site-packages/django/template/response.py", line 107, in render
    self.content = self.rendered_content
  File "/Users/zy/env/webpyenv/lib/python2.7/site-packages/django/template/response.py", line 82, in rendered_content
    template = self.resolve_template(self.template_name)
  File "/Users/zy/env/webpyenv/lib/python2.7/site-packages/django/template/response.py", line 64, in resolve_template
    return select_template(template, using=self.using)
  File "/Users/zy/env/webpyenv/lib/python2.7/site-packages/django/template/loader.py", line 48, in select_template
    return engine.get_template(template_name)
  File "/Users/zy/env/webpyenv/lib/python2.7/site-packages/django/template/backends/django.py", line 39, in get_template
    return Template(self.engine.get_template(template_name), self)
  File "/Users/zy/env/webpyenv/lib/python2.7/site-packages/django/template/engine.py", line 162, in get_template
    template, origin = self.find_template(template_name)
  File "/Users/zy/env/webpyenv/lib/python2.7/site-packages/django/template/engine.py", line 136, in find_template
    name, template_dirs=dirs, skip=skip,
  File "/Users/zy/env/webpyenv/lib/python2.7/site-packages/django/template/loaders/base.py", line 44, in get_template
    contents, origin, origin.template_name, self.engine,
  File "/Users/zy/env/webpyenv/lib/python2.7/site-packages/django/template/base.py", line 191, in __init__
    self.nodelist = self.compile_nodelist()
  File "/Users/zy/env/webpyenv/lib/python2.7/site-packages/django/template/base.py", line 230, in compile_nodelist
    return parser.parse()
  File "/Users/zy/env/webpyenv/lib/python2.7/site-packages/django/template/base.py", line 515, in parse
    raise self.error(token, e)
TemplateSyntaxError: Invalid block tag on line 58: 'bootstrap_pagination', expected 'endblock'. Did you forget to register or load this tag?
2017-11-08 17:23:35,498 [CASdjango.request] [Thread-8] ERROR [/Users/zy/env/webpyenv/lib/python2.7/site-packages/django/core/handlers/exception.py--line:135] Internal Server Error: /product/list/
Traceback (most recent call last):
  File "/Users/zy/env/webpyenv/lib/python2.7/site-packages/django/core/handlers/exception.py", line 41, in inner
    response = get_response(request)
  File "/Users/zy/env/webpyenv/lib/python2.7/site-packages/django/core/handlers/base.py", line 217, in _get_response
    response = self.process_exception_by_middleware(e, request)
  File "/Users/zy/env/webpyenv/lib/python2.7/site-packages/django/core/handlers/base.py", line 215, in _get_response
    response = response.render()
  File "/Users/zy/env/webpyenv/lib/python2.7/site-packages/django/template/response.py", line 107, in render
    self.content = self.rendered_content
  File "/Users/zy/env/webpyenv/lib/python2.7/site-packages/django/template/response.py", line 82, in rendered_content
    template = self.resolve_template(self.template_name)
  File "/Users/zy/env/webpyenv/lib/python2.7/site-packages/django/template/response.py", line 64, in resolve_template
    return select_template(template, using=self.using)
  File "/Users/zy/env/webpyenv/lib/python2.7/site-packages/django/template/loader.py", line 48, in select_template
    return engine.get_template(template_name)
  File "/Users/zy/env/webpyenv/lib/python2.7/site-packages/django/template/backends/django.py", line 39, in get_template
    return Template(self.engine.get_template(template_name), self)
  File "/Users/zy/env/webpyenv/lib/python2.7/site-packages/django/template/engine.py", line 162, in get_template
    template, origin = self.find_template(template_name)
  File "/Users/zy/env/webpyenv/lib/python2.7/site-packages/django/template/engine.py", line 136, in find_template
    name, template_dirs=dirs, skip=skip,
  File "/Users/zy/env/webpyenv/lib/python2.7/site-packages/django/template/loaders/base.py", line 44, in get_template
    contents, origin, origin.template_name, self.engine,
  File "/Users/zy/env/webpyenv/lib/python2.7/site-packages/django/template/base.py", line 191, in __init__
    self.nodelist = self.compile_nodelist()
  File "/Users/zy/env/webpyenv/lib/python2.7/site-packages/django/template/base.py", line 230, in compile_nodelist
    return parser.parse()
  File "/Users/zy/env/webpyenv/lib/python2.7/site-packages/django/template/base.py", line 515, in parse
    raise self.error(token, e)
TemplateSyntaxError: Invalid block tag on line 58: 'bootstrap_pagination', expected 'endblock'. Did you forget to register or load this tag?
2017-11-08 17:23:36,302 [CASdjango.request] [Thread-9] ERROR [/Users/zy/env/webpyenv/lib/python2.7/site-packages/django/core/handlers/exception.py--line:135] Internal Server Error: /product/list/
Traceback (most recent call last):
  File "/Users/zy/env/webpyenv/lib/python2.7/site-packages/django/core/handlers/exception.py", line 41, in inner
    response = get_response(request)
  File "/Users/zy/env/webpyenv/lib/python2.7/site-packages/django/core/handlers/base.py", line 217, in _get_response
    response = self.process_exception_by_middleware(e, request)
  File "/Users/zy/env/webpyenv/lib/python2.7/site-packages/django/core/handlers/base.py", line 215, in _get_response
    response = response.render()
  File "/Users/zy/env/webpyenv/lib/python2.7/site-packages/django/template/response.py", line 107, in render
    self.content = self.rendered_content
  File "/Users/zy/env/webpyenv/lib/python2.7/site-packages/django/template/response.py", line 82, in rendered_content
    template = self.resolve_template(self.template_name)
  File "/Users/zy/env/webpyenv/lib/python2.7/site-packages/django/template/response.py", line 64, in resolve_template
    return select_template(template, using=self.using)
  File "/Users/zy/env/webpyenv/lib/python2.7/site-packages/django/template/loader.py", line 48, in select_template
    return engine.get_template(template_name)
  File "/Users/zy/env/webpyenv/lib/python2.7/site-packages/django/template/backends/django.py", line 39, in get_template
    return Template(self.engine.get_template(template_name), self)
  File "/Users/zy/env/webpyenv/lib/python2.7/site-packages/django/template/engine.py", line 162, in get_template
    template, origin = self.find_template(template_name)
  File "/Users/zy/env/webpyenv/lib/python2.7/site-packages/django/template/engine.py", line 136, in find_template
    name, template_dirs=dirs, skip=skip,
  File "/Users/zy/env/webpyenv/lib/python2.7/site-packages/django/template/loaders/base.py", line 44, in get_template
    contents, origin, origin.template_name, self.engine,
  File "/Users/zy/env/webpyenv/lib/python2.7/site-packages/django/template/base.py", line 191, in __init__
    self.nodelist = self.compile_nodelist()
  File "/Users/zy/env/webpyenv/lib/python2.7/site-packages/django/template/base.py", line 230, in compile_nodelist
    return parser.parse()
  File "/Users/zy/env/webpyenv/lib/python2.7/site-packages/django/template/base.py", line 515, in parse
    raise self.error(token, e)
TemplateSyntaxError: Invalid block tag on line 58: 'bootstrap_pagination', expected 'endblock'. Did you forget to register or load this tag?
2017-11-08 17:23:37,294 [CASdjango.request] [Thread-10] ERROR [/Users/zy/env/webpyenv/lib/python2.7/site-packages/django/core/handlers/exception.py--line:135] Internal Server Error: /product/list/
Traceback (most recent call last):
  File "/Users/zy/env/webpyenv/lib/python2.7/site-packages/django/core/handlers/exception.py", line 41, in inner
    response = get_response(request)
  File "/Users/zy/env/webpyenv/lib/python2.7/site-packages/django/core/handlers/base.py", line 217, in _get_response
    response = self.process_exception_by_middleware(e, request)
  File "/Users/zy/env/webpyenv/lib/python2.7/site-packages/django/core/handlers/base.py", line 215, in _get_response
    response = response.render()
  File "/Users/zy/env/webpyenv/lib/python2.7/site-packages/django/template/response.py", line 107, in render
    self.content = self.rendered_content
  File "/Users/zy/env/webpyenv/lib/python2.7/site-packages/django/template/response.py", line 82, in rendered_content
    template = self.resolve_template(self.template_name)
  File "/Users/zy/env/webpyenv/lib/python2.7/site-packages/django/template/response.py", line 64, in resolve_template
    return select_template(template, using=self.using)
  File "/Users/zy/env/webpyenv/lib/python2.7/site-packages/django/template/loader.py", line 48, in select_template
    return engine.get_template(template_name)
  File "/Users/zy/env/webpyenv/lib/python2.7/site-packages/django/template/backends/django.py", line 39, in get_template
    return Template(self.engine.get_template(template_name), self)
  File "/Users/zy/env/webpyenv/lib/python2.7/site-packages/django/template/engine.py", line 162, in get_template
    template, origin = self.find_template(template_name)
  File "/Users/zy/env/webpyenv/lib/python2.7/site-packages/django/template/engine.py", line 136, in find_template
    name, template_dirs=dirs, skip=skip,
  File "/Users/zy/env/webpyenv/lib/python2.7/site-packages/django/template/loaders/base.py", line 44, in get_template
    contents, origin, origin.template_name, self.engine,
  File "/Users/zy/env/webpyenv/lib/python2.7/site-packages/django/template/base.py", line 191, in __init__
    self.nodelist = self.compile_nodelist()
  File "/Users/zy/env/webpyenv/lib/python2.7/site-packages/django/template/base.py", line 230, in compile_nodelist
    return parser.parse()
  File "/Users/zy/env/webpyenv/lib/python2.7/site-packages/django/template/base.py", line 515, in parse
    raise self.error(token, e)
TemplateSyntaxError: Invalid block tag on line 58: 'bootstrap_pagination', expected 'endblock'. Did you forget to register or load this tag?
2017-11-08 17:29:02,532 [CASdjango.request] [Thread-1] ERROR [/Users/zy/env/webpyenv/lib/python2.7/site-packages/django/core/handlers/exception.py--line:135] Internal Server Error: /product/list/
Traceback (most recent call last):
  File "/Users/zy/env/webpyenv/lib/python2.7/site-packages/django/core/handlers/exception.py", line 41, in inner
    response = get_response(request)
  File "/Users/zy/env/webpyenv/lib/python2.7/site-packages/django/core/handlers/base.py", line 217, in _get_response
    response = self.process_exception_by_middleware(e, request)
  File "/Users/zy/env/webpyenv/lib/python2.7/site-packages/django/core/handlers/base.py", line 215, in _get_response
    response = response.render()
  File "/Users/zy/env/webpyenv/lib/python2.7/site-packages/django/template/response.py", line 107, in render
    self.content = self.rendered_content
  File "/Users/zy/env/webpyenv/lib/python2.7/site-packages/django/template/response.py", line 82, in rendered_content
    template = self.resolve_template(self.template_name)
  File "/Users/zy/env/webpyenv/lib/python2.7/site-packages/django/template/response.py", line 64, in resolve_template
    return select_template(template, using=self.using)
  File "/Users/zy/env/webpyenv/lib/python2.7/site-packages/django/template/loader.py", line 48, in select_template
    return engine.get_template(template_name)
  File "/Users/zy/env/webpyenv/lib/python2.7/site-packages/django/template/backends/django.py", line 39, in get_template
    return Template(self.engine.get_template(template_name), self)
  File "/Users/zy/env/webpyenv/lib/python2.7/site-packages/django/template/engine.py", line 162, in get_template
    template, origin = self.find_template(template_name)
  File "/Users/zy/env/webpyenv/lib/python2.7/site-packages/django/template/engine.py", line 136, in find_template
    name, template_dirs=dirs, skip=skip,
  File "/Users/zy/env/webpyenv/lib/python2.7/site-packages/django/template/loaders/base.py", line 44, in get_template
    contents, origin, origin.template_name, self.engine,
  File "/Users/zy/env/webpyenv/lib/python2.7/site-packages/django/template/base.py", line 191, in __init__
    self.nodelist = self.compile_nodelist()
  File "/Users/zy/env/webpyenv/lib/python2.7/site-packages/django/template/base.py", line 230, in compile_nodelist
    return parser.parse()
  File "/Users/zy/env/webpyenv/lib/python2.7/site-packages/django/template/base.py", line 515, in parse
    raise self.error(token, e)
TemplateSyntaxError: 'bootstrap3' is not a registered tag library. Must be one of:
admin_list
admin_modify
admin_static
admin_urls
cache
i18n
l10n
log
static
staticfiles
tz
2017-11-08 17:29:06,586 [CASdjango.request] [Thread-3] ERROR [/Users/zy/env/webpyenv/lib/python2.7/site-packages/django/core/handlers/exception.py--line:135] Internal Server Error: /product/list/
Traceback (most recent call last):
  File "/Users/zy/env/webpyenv/lib/python2.7/site-packages/django/core/handlers/exception.py", line 41, in inner
    response = get_response(request)
  File "/Users/zy/env/webpyenv/lib/python2.7/site-packages/django/core/handlers/base.py", line 217, in _get_response
    response = self.process_exception_by_middleware(e, request)
  File "/Users/zy/env/webpyenv/lib/python2.7/site-packages/django/core/handlers/base.py", line 215, in _get_response
    response = response.render()
  File "/Users/zy/env/webpyenv/lib/python2.7/site-packages/django/template/response.py", line 107, in render
    self.content = self.rendered_content
  File "/Users/zy/env/webpyenv/lib/python2.7/site-packages/django/template/response.py", line 82, in rendered_content
    template = self.resolve_template(self.template_name)
  File "/Users/zy/env/webpyenv/lib/python2.7/site-packages/django/template/response.py", line 64, in resolve_template
    return select_template(template, using=self.using)
  File "/Users/zy/env/webpyenv/lib/python2.7/site-packages/django/template/loader.py", line 48, in select_template
    return engine.get_template(template_name)
  File "/Users/zy/env/webpyenv/lib/python2.7/site-packages/django/template/backends/django.py", line 39, in get_template
    return Template(self.engine.get_template(template_name), self)
  File "/Users/zy/env/webpyenv/lib/python2.7/site-packages/django/template/engine.py", line 162, in get_template
    template, origin = self.find_template(template_name)
  File "/Users/zy/env/webpyenv/lib/python2.7/site-packages/django/template/engine.py", line 136, in find_template
    name, template_dirs=dirs, skip=skip,
  File "/Users/zy/env/webpyenv/lib/python2.7/site-packages/django/template/loaders/base.py", line 44, in get_template
    contents, origin, origin.template_name, self.engine,
  File "/Users/zy/env/webpyenv/lib/python2.7/site-packages/django/template/base.py", line 191, in __init__
    self.nodelist = self.compile_nodelist()
  File "/Users/zy/env/webpyenv/lib/python2.7/site-packages/django/template/base.py", line 230, in compile_nodelist
    return parser.parse()
  File "/Users/zy/env/webpyenv/lib/python2.7/site-packages/django/template/base.py", line 515, in parse
    raise self.error(token, e)
TemplateSyntaxError: 'bootstrap3' is not a registered tag library. Must be one of:
admin_list
admin_modify
admin_static
admin_urls
cache
i18n
l10n
log
static
staticfiles
tz
2017-11-08 17:31:51,091 [CASdjango.request] [Thread-5] ERROR [/Users/zy/env/webpyenv/lib/python2.7/site-packages/django/core/handlers/exception.py--line:135] Internal Server Error: /product/list/
Traceback (most recent call last):
  File "/Users/zy/env/webpyenv/lib/python2.7/site-packages/django/core/handlers/exception.py", line 41, in inner
    response = get_response(request)
  File "/Users/zy/env/webpyenv/lib/python2.7/site-packages/django/core/handlers/base.py", line 217, in _get_response
    response = self.process_exception_by_middleware(e, request)
  File "/Users/zy/env/webpyenv/lib/python2.7/site-packages/django/core/handlers/base.py", line 215, in _get_response
    response = response.render()
  File "/Users/zy/env/webpyenv/lib/python2.7/site-packages/django/template/response.py", line 107, in render
    self.content = self.rendered_content
  File "/Users/zy/env/webpyenv/lib/python2.7/site-packages/django/template/response.py", line 82, in rendered_content
    template = self.resolve_template(self.template_name)
  File "/Users/zy/env/webpyenv/lib/python2.7/site-packages/django/template/response.py", line 64, in resolve_template
    return select_template(template, using=self.using)
  File "/Users/zy/env/webpyenv/lib/python2.7/site-packages/django/template/loader.py", line 48, in select_template
    return engine.get_template(template_name)
  File "/Users/zy/env/webpyenv/lib/python2.7/site-packages/django/template/backends/django.py", line 39, in get_template
    return Template(self.engine.get_template(template_name), self)
  File "/Users/zy/env/webpyenv/lib/python2.7/site-packages/django/template/engine.py", line 162, in get_template
    template, origin = self.find_template(template_name)
  File "/Users/zy/env/webpyenv/lib/python2.7/site-packages/django/template/engine.py", line 136, in find_template
    name, template_dirs=dirs, skip=skip,
  File "/Users/zy/env/webpyenv/lib/python2.7/site-packages/django/template/loaders/base.py", line 44, in get_template
    contents, origin, origin.template_name, self.engine,
  File "/Users/zy/env/webpyenv/lib/python2.7/site-packages/django/template/base.py", line 191, in __init__
    self.nodelist = self.compile_nodelist()
  File "/Users/zy/env/webpyenv/lib/python2.7/site-packages/django/template/base.py", line 230, in compile_nodelist
    return parser.parse()
  File "/Users/zy/env/webpyenv/lib/python2.7/site-packages/django/template/base.py", line 515, in parse
    raise self.error(token, e)
TemplateSyntaxError: 'bootstrap3' is not a registered tag library. Must be one of:
admin_list
admin_modify
admin_static
admin_urls
cache
i18n
l10n
log
static
staticfiles
tz
2017-11-08 17:31:51,636 [CASdjango.request] [Thread-6] ERROR [/Users/zy/env/webpyenv/lib/python2.7/site-packages/django/core/handlers/exception.py--line:135] Internal Server Error: /product/list/
Traceback (most recent call last):
  File "/Users/zy/env/webpyenv/lib/python2.7/site-packages/django/core/handlers/exception.py", line 41, in inner
    response = get_response(request)
  File "/Users/zy/env/webpyenv/lib/python2.7/site-packages/django/core/handlers/base.py", line 217, in _get_response
    response = self.process_exception_by_middleware(e, request)
  File "/Users/zy/env/webpyenv/lib/python2.7/site-packages/django/core/handlers/base.py", line 215, in _get_response
    response = response.render()
  File "/Users/zy/env/webpyenv/lib/python2.7/site-packages/django/template/response.py", line 107, in render
    self.content = self.rendered_content
  File "/Users/zy/env/webpyenv/lib/python2.7/site-packages/django/template/response.py", line 82, in rendered_content
    template = self.resolve_template(self.template_name)
  File "/Users/zy/env/webpyenv/lib/python2.7/site-packages/django/template/response.py", line 64, in resolve_template
    return select_template(template, using=self.using)
  File "/Users/zy/env/webpyenv/lib/python2.7/site-packages/django/template/loader.py", line 48, in select_template
    return engine.get_template(template_name)
  File "/Users/zy/env/webpyenv/lib/python2.7/site-packages/django/template/backends/django.py", line 39, in get_template
    return Template(self.engine.get_template(template_name), self)
  File "/Users/zy/env/webpyenv/lib/python2.7/site-packages/django/template/engine.py", line 162, in get_template
    template, origin = self.find_template(template_name)
  File "/Users/zy/env/webpyenv/lib/python2.7/site-packages/django/template/engine.py", line 136, in find_template
    name, template_dirs=dirs, skip=skip,
  File "/Users/zy/env/webpyenv/lib/python2.7/site-packages/django/template/loaders/base.py", line 44, in get_template
    contents, origin, origin.template_name, self.engine,
  File "/Users/zy/env/webpyenv/lib/python2.7/site-packages/django/template/base.py", line 191, in __init__
    self.nodelist = self.compile_nodelist()
  File "/Users/zy/env/webpyenv/lib/python2.7/site-packages/django/template/base.py", line 230, in compile_nodelist
    return parser.parse()
  File "/Users/zy/env/webpyenv/lib/python2.7/site-packages/django/template/base.py", line 515, in parse
    raise self.error(token, e)
TemplateSyntaxError: 'bootstrap3' is not a registered tag library. Must be one of:
admin_list
admin_modify
admin_static
admin_urls
cache
i18n
l10n
log
static
staticfiles
tz
2017-11-08 17:31:52,119 [CASdjango.request] [Thread-7] ERROR [/Users/zy/env/webpyenv/lib/python2.7/site-packages/django/core/handlers/exception.py--line:135] Internal Server Error: /product/list/
Traceback (most recent call last):
  File "/Users/zy/env/webpyenv/lib/python2.7/site-packages/django/core/handlers/exception.py", line 41, in inner
    response = get_response(request)
  File "/Users/zy/env/webpyenv/lib/python2.7/site-packages/django/core/handlers/base.py", line 217, in _get_response
    response = self.process_exception_by_middleware(e, request)
  File "/Users/zy/env/webpyenv/lib/python2.7/site-packages/django/core/handlers/base.py", line 215, in _get_response
    response = response.render()
  File "/Users/zy/env/webpyenv/lib/python2.7/site-packages/django/template/response.py", line 107, in render
    self.content = self.rendered_content
  File "/Users/zy/env/webpyenv/lib/python2.7/site-packages/django/template/response.py", line 82, in rendered_content
    template = self.resolve_template(self.template_name)
  File "/Users/zy/env/webpyenv/lib/python2.7/site-packages/django/template/response.py", line 64, in resolve_template
    return select_template(template, using=self.using)
  File "/Users/zy/env/webpyenv/lib/python2.7/site-packages/django/template/loader.py", line 48, in select_template
    return engine.get_template(template_name)
  File "/Users/zy/env/webpyenv/lib/python2.7/site-packages/django/template/backends/django.py", line 39, in get_template
    return Template(self.engine.get_template(template_name), self)
  File "/Users/zy/env/webpyenv/lib/python2.7/site-packages/django/template/engine.py", line 162, in get_template
    template, origin = self.find_template(template_name)
  File "/Users/zy/env/webpyenv/lib/python2.7/site-packages/django/template/engine.py", line 136, in find_template
    name, template_dirs=dirs, skip=skip,
  File "/Users/zy/env/webpyenv/lib/python2.7/site-packages/django/template/loaders/base.py", line 44, in get_template
    contents, origin, origin.template_name, self.engine,
  File "/Users/zy/env/webpyenv/lib/python2.7/site-packages/django/template/base.py", line 191, in __init__
    self.nodelist = self.compile_nodelist()
  File "/Users/zy/env/webpyenv/lib/python2.7/site-packages/django/template/base.py", line 230, in compile_nodelist
    return parser.parse()
  File "/Users/zy/env/webpyenv/lib/python2.7/site-packages/django/template/base.py", line 515, in parse
    raise self.error(token, e)
TemplateSyntaxError: 'bootstrap3' is not a registered tag library. Must be one of:
admin_list
admin_modify
admin_static
admin_urls
cache
i18n
l10n
log
static
staticfiles
tz
2017-11-08 17:31:55,236 [CASdjango.request] [Thread-8] ERROR [/Users/zy/env/webpyenv/lib/python2.7/site-packages/django/core/handlers/exception.py--line:135] Internal Server Error: /product/list/
Traceback (most recent call last):
  File "/Users/zy/env/webpyenv/lib/python2.7/site-packages/django/core/handlers/exception.py", line 41, in inner
    response = get_response(request)
  File "/Users/zy/env/webpyenv/lib/python2.7/site-packages/django/core/handlers/base.py", line 217, in _get_response
    response = self.process_exception_by_middleware(e, request)
  File "/Users/zy/env/webpyenv/lib/python2.7/site-packages/django/core/handlers/base.py", line 215, in _get_response
    response = response.render()
  File "/Users/zy/env/webpyenv/lib/python2.7/site-packages/django/template/response.py", line 107, in render
    self.content = self.rendered_content
  File "/Users/zy/env/webpyenv/lib/python2.7/site-packages/django/template/response.py", line 82, in rendered_content
    template = self.resolve_template(self.template_name)
  File "/Users/zy/env/webpyenv/lib/python2.7/site-packages/django/template/response.py", line 64, in resolve_template
    return select_template(template, using=self.using)
  File "/Users/zy/env/webpyenv/lib/python2.7/site-packages/django/template/loader.py", line 48, in select_template
    return engine.get_template(template_name)
  File "/Users/zy/env/webpyenv/lib/python2.7/site-packages/django/template/backends/django.py", line 39, in get_template
    return Template(self.engine.get_template(template_name), self)
  File "/Users/zy/env/webpyenv/lib/python2.7/site-packages/django/template/engine.py", line 162, in get_template
    template, origin = self.find_template(template_name)
  File "/Users/zy/env/webpyenv/lib/python2.7/site-packages/django/template/engine.py", line 136, in find_template
    name, template_dirs=dirs, skip=skip,
  File "/Users/zy/env/webpyenv/lib/python2.7/site-packages/django/template/loaders/base.py", line 44, in get_template
    contents, origin, origin.template_name, self.engine,
  File "/Users/zy/env/webpyenv/lib/python2.7/site-packages/django/template/base.py", line 191, in __init__
    self.nodelist = self.compile_nodelist()
  File "/Users/zy/env/webpyenv/lib/python2.7/site-packages/django/template/base.py", line 230, in compile_nodelist
    return parser.parse()
  File "/Users/zy/env/webpyenv/lib/python2.7/site-packages/django/template/base.py", line 515, in parse
    raise self.error(token, e)
TemplateSyntaxError: 'bootstrap3' is not a registered tag library. Must be one of:
admin_list
admin_modify
admin_static
admin_urls
cache
i18n
l10n
log
static
staticfiles
tz
2017-11-08 18:00:49,206 [CASdjango.request] [Thread-1] ERROR [/Users/zy/env/webpyenv/lib/python2.7/site-packages/django/core/handlers/exception.py--line:135] Internal Server Error: /order/list/
Traceback (most recent call last):
  File "/Users/zy/env/webpyenv/lib/python2.7/site-packages/django/core/handlers/exception.py", line 41, in inner
    response = get_response(request)
  File "/Users/zy/env/webpyenv/lib/python2.7/site-packages/django/core/handlers/base.py", line 187, in _get_response
    response = self.process_exception_by_middleware(e, request)
  File "/Users/zy/env/webpyenv/lib/python2.7/site-packages/django/core/handlers/base.py", line 185, in _get_response
    response = wrapped_callback(request, *callback_args, **callback_kwargs)
  File "/Users/zy/env/webpyenv/lib/python2.7/site-packages/django/views/generic/base.py", line 68, in view
    return self.dispatch(request, *args, **kwargs)
  File "/Users/zy/env/webpyenv/lib/python2.7/site-packages/django/views/generic/base.py", line 88, in dispatch
    return handler(request, *args, **kwargs)
  File "/Users/zy/env/webpyenv/lib/python2.7/site-packages/django/views/generic/list.py", line 175, in get
    context = self.get_context_data()
  File "/Users/zy/Project/wjnhadmin/orders/views.py", line 41, in get_context_data
    context['extra_url_param'] = urlencode({'show': self.show, 'my': self.my, 'state': self.state})
AttributeError: 'OrderList' object has no attribute 'show'
2017-11-08 18:01:04,522 [CASdjango.request] [Thread-5] ERROR [/Users/zy/env/webpyenv/lib/python2.7/site-packages/django/core/handlers/exception.py--line:135] Internal Server Error: /order/list/
Traceback (most recent call last):
  File "/Users/zy/env/webpyenv/lib/python2.7/site-packages/django/core/handlers/exception.py", line 41, in inner
    response = get_response(request)
  File "/Users/zy/env/webpyenv/lib/python2.7/site-packages/django/core/handlers/base.py", line 187, in _get_response
    response = self.process_exception_by_middleware(e, request)
  File "/Users/zy/env/webpyenv/lib/python2.7/site-packages/django/core/handlers/base.py", line 185, in _get_response
    response = wrapped_callback(request, *callback_args, **callback_kwargs)
  File "/Users/zy/env/webpyenv/lib/python2.7/site-packages/django/views/generic/base.py", line 68, in view
    return self.dispatch(request, *args, **kwargs)
  File "/Users/zy/env/webpyenv/lib/python2.7/site-packages/django/views/generic/base.py", line 88, in dispatch
    return handler(request, *args, **kwargs)
  File "/Users/zy/env/webpyenv/lib/python2.7/site-packages/django/views/generic/list.py", line 175, in get
    context = self.get_context_data()
  File "/Users/zy/Project/wjnhadmin/orders/views.py", line 41, in get_context_data
    # context['extra_url_param'] = urlencode({'show': self.show, 'my': self.my, 'state': self.state})
AttributeError: 'OrderList' object has no attribute 'show'
2017-11-09 10:48:37,275 [CASdjango.request] [Thread-4] ERROR [/Users/zy/env/webpyenv/lib/python2.7/site-packages/django/core/handlers/exception.py--line:135] Internal Server Error: /product/10000001/detail/
Traceback (most recent call last):
  File "/Users/zy/env/webpyenv/lib/python2.7/site-packages/django/core/handlers/exception.py", line 41, in inner
    response = get_response(request)
  File "/Users/zy/env/webpyenv/lib/python2.7/site-packages/django/core/handlers/base.py", line 217, in _get_response
    response = self.process_exception_by_middleware(e, request)
  File "/Users/zy/env/webpyenv/lib/python2.7/site-packages/django/core/handlers/base.py", line 215, in _get_response
    response = response.render()
  File "/Users/zy/env/webpyenv/lib/python2.7/site-packages/django/template/response.py", line 107, in render
    self.content = self.rendered_content
  File "/Users/zy/env/webpyenv/lib/python2.7/site-packages/django/template/response.py", line 82, in rendered_content
    template = self.resolve_template(self.template_name)
  File "/Users/zy/env/webpyenv/lib/python2.7/site-packages/django/template/response.py", line 64, in resolve_template
    return select_template(template, using=self.using)
  File "/Users/zy/env/webpyenv/lib/python2.7/site-packages/django/template/loader.py", line 53, in select_template
    raise TemplateDoesNotExist(', '.join(template_name_list), chain=chain)
TemplateDoesNotExist: product-detail.html
2017-11-09 10:51:21,332 [CASdjango.request] [Thread-13] ERROR [/Users/zy/env/webpyenv/lib/python2.7/site-packages/django/core/handlers/exception.py--line:135] Internal Server Error: /product/list/
Traceback (most recent call last):
  File "/Users/zy/env/webpyenv/lib/python2.7/site-packages/django/core/handlers/exception.py", line 41, in inner
    response = get_response(request)
  File "/Users/zy/env/webpyenv/lib/python2.7/site-packages/django/core/handlers/base.py", line 217, in _get_response
    response = self.process_exception_by_middleware(e, request)
  File "/Users/zy/env/webpyenv/lib/python2.7/site-packages/django/core/handlers/base.py", line 215, in _get_response
    response = response.render()
  File "/Users/zy/env/webpyenv/lib/python2.7/site-packages/django/template/response.py", line 107, in render
    self.content = self.rendered_content
  File "/Users/zy/env/webpyenv/lib/python2.7/site-packages/django/template/response.py", line 82, in rendered_content
    template = self.resolve_template(self.template_name)
  File "/Users/zy/env/webpyenv/lib/python2.7/site-packages/django/template/response.py", line 64, in resolve_template
    return select_template(template, using=self.using)
  File "/Users/zy/env/webpyenv/lib/python2.7/site-packages/django/template/loader.py", line 48, in select_template
    return engine.get_template(template_name)
  File "/Users/zy/env/webpyenv/lib/python2.7/site-packages/django/template/backends/django.py", line 39, in get_template
    return Template(self.engine.get_template(template_name), self)
  File "/Users/zy/env/webpyenv/lib/python2.7/site-packages/django/template/engine.py", line 162, in get_template
    template, origin = self.find_template(template_name)
  File "/Users/zy/env/webpyenv/lib/python2.7/site-packages/django/template/engine.py", line 136, in find_template
    name, template_dirs=dirs, skip=skip,
  File "/Users/zy/env/webpyenv/lib/python2.7/site-packages/django/template/loaders/base.py", line 44, in get_template
    contents, origin, origin.template_name, self.engine,
  File "/Users/zy/env/webpyenv/lib/python2.7/site-packages/django/template/base.py", line 191, in __init__
    self.nodelist = self.compile_nodelist()
  File "/Users/zy/env/webpyenv/lib/python2.7/site-packages/django/template/base.py", line 230, in compile_nodelist
    return parser.parse()
  File "/Users/zy/env/webpyenv/lib/python2.7/site-packages/django/template/base.py", line 515, in parse
    raise self.error(token, e)
TemplateSyntaxError: Invalid block tag on line 58: 'bootstrap_pagination', expected 'endblock'. Did you forget to register or load this tag?
2017-11-09 10:51:33,677 [CASdjango.request] [Thread-16] ERROR [/Users/zy/env/webpyenv/lib/python2.7/site-packages/django/core/handlers/exception.py--line:135] Internal Server Error: /product/list/
Traceback (most recent call last):
  File "/Users/zy/env/webpyenv/lib/python2.7/site-packages/django/core/handlers/exception.py", line 41, in inner
    response = get_response(request)
  File "/Users/zy/env/webpyenv/lib/python2.7/site-packages/django/core/handlers/base.py", line 217, in _get_response
    response = self.process_exception_by_middleware(e, request)
  File "/Users/zy/env/webpyenv/lib/python2.7/site-packages/django/core/handlers/base.py", line 215, in _get_response
    response = response.render()
  File "/Users/zy/env/webpyenv/lib/python2.7/site-packages/django/template/response.py", line 107, in render
    self.content = self.rendered_content
  File "/Users/zy/env/webpyenv/lib/python2.7/site-packages/django/template/response.py", line 82, in rendered_content
    template = self.resolve_template(self.template_name)
  File "/Users/zy/env/webpyenv/lib/python2.7/site-packages/django/template/response.py", line 64, in resolve_template
    return select_template(template, using=self.using)
  File "/Users/zy/env/webpyenv/lib/python2.7/site-packages/django/template/loader.py", line 48, in select_template
    return engine.get_template(template_name)
  File "/Users/zy/env/webpyenv/lib/python2.7/site-packages/django/template/backends/django.py", line 39, in get_template
    return Template(self.engine.get_template(template_name), self)
  File "/Users/zy/env/webpyenv/lib/python2.7/site-packages/django/template/engine.py", line 162, in get_template
    template, origin = self.find_template(template_name)
  File "/Users/zy/env/webpyenv/lib/python2.7/site-packages/django/template/engine.py", line 136, in find_template
    name, template_dirs=dirs, skip=skip,
  File "/Users/zy/env/webpyenv/lib/python2.7/site-packages/django/template/loaders/base.py", line 44, in get_template
    contents, origin, origin.template_name, self.engine,
  File "/Users/zy/env/webpyenv/lib/python2.7/site-packages/django/template/base.py", line 191, in __init__
    self.nodelist = self.compile_nodelist()
  File "/Users/zy/env/webpyenv/lib/python2.7/site-packages/django/template/base.py", line 230, in compile_nodelist
    return parser.parse()
  File "/Users/zy/env/webpyenv/lib/python2.7/site-packages/django/template/base.py", line 515, in parse
    raise self.error(token, e)
TemplateSyntaxError: Invalid block tag on line 58: 'bootstrap_pagination', expected 'endblock'. Did you forget to register or load this tag?
